Workbook

Sheet Data Kumpulan
A1: urut | B1: desa/kota | C1: penimbang | D1: sumber air minum | E1: sumber air mck | F1: keruh | G1: berwarna | H1: berasa | I1: berbusa | J1: berbau
A2: 500040 | B2: 1 | C2: 28.466245 | D2: 4 | E2: 4 | F2: 5 | G2: 5 | H2: 5 | I2: 5 | J2: 5
A3: 500044 | B3: 1 | C3: 120.27253 | D3: 5 | E3: 5 | F3: 5 | G3: 5 | H3: 5 | I3: 5 | J3: 5
A4: 500046 | B4: 1 | C4: 1044.4816 | D4: 5 | E4: 5 | F4: 5 | G4: 5 | H4: 5 | I4: 5 | J4: 5
A5: 500053 | B5: 1 | C5: 1449.6065 | D5: 7 | E5: 7 | F5: 5 | G5: 5 | H5: 5 | I5: 5 | J5: 5
A6: 500054 | B6: 2 | C6: 26.987807 | D6: 7 | E6: 7 | F6: 5 | G6: 5 | H6: 5 | I6: 5 | J6: 5
A7: 500061 | B7: 2 | C7: 420.70705 | D7: 5 | E7: 5 | F7: 5 | G7: 5 | H7: 5 | I7: 5 | J7: 5
A8: 500072 | B8: 2 | C8: 138.35535 | D8: 7 | E8: 8 | F8: 5 | G8: 5 | H8: 5 | I8: 5 | J8: 5
A9: 500076 | B9: 2 | C9: 722.57353 | D9: 7 | E9: 7 | F9: 5 | G9: 5 | H9: 5 | I9: 5 | J9: 5
A10: 500124 | B10: 2 | C10: 411.07108 | D10: 8 | E10: 8 | F10: 5 | G10: 5 | H10: 5 | I10: 5 | J10: 5
A11: 500140 | B11: 1 | C11: 406.9041 | D11: 2 | E11: 9 | F11: 5 | G11: 5 | H11: 5 | I11: 5 | J11: 5
A12: 500148 | B12: 2 | C12: 415.11245 | D12: 6 | E12: 4 | F12: 5 | G12: 5 | H12: 5 | I12: 5 | J12: 5
A13: 500149 | B13: 2 | C13: 238.97449 | D13: 8 | E13: 8 | F13: 5 | G13: 5 | H13: 5 | I13: 5 | J13: 5
... A1130: 525873 | B1130: 1 | C1130: 1247.9542 | D1130: 1 | E1130: 4 | F1130: 5 | G1130: 5 | H1130: 5 | I1130: 5 | J1130: 5

Sheet Sheet5
A1: keruh | B1: kota/desa | C1: penimbang
A2: =IF('Data Kumpulan'!F2=1,"Ya","Tidak") -> Tidak | B2: =IF('Data Kumpulan'!B2=1,"Perkotaan","Pedesaan") -> Perkotaan | C2: 28.466245
B3: =IF('Data Kumpulan'!B3=1,"Perkotaan","Pedesaan") -> Perkotaan | C3: 120.27253
B4: =IF('Data Kumpulan'!B4=1,"Perkotaan","Pedesaan") -> Perkotaan | C4: 1044.4816
B5: =IF('Data Kumpulan'!B5=1,"Perkotaan","Pedesaan") -> Perkotaan | C5: 1449.6065
B6: =IF('Data Kumpulan'!B6=1,"Perkotaan","Pedesaan") -> Pedesaan | C6: 26.987807
B7: =IF('Data Kumpulan'!B7=1,"Perkotaan","Pedesaan") -> Pedesaan | C7: 420.70705
B8: =IF('Data Kumpulan'!B8=1,"Perkotaan","Pedesaan") -> Pedesaan | C8: 138.35535
B9: =IF('Data Kumpulan'!B9=1,"Perkotaan","Pedesaan") -> Pedesaan | C9: 722.57353
B10: =IF('Data Kumpulan'!B10=1,"Perkotaan","Pedesaan") -> Pedesaan | C10: 411.07108
B11: =IF('Data Kumpulan'!B11=1,"Perkotaan","Pedesaan") -> Perkotaan | C11: 406.9041
B12: =IF('Data Kumpulan'!B12=1,"Perkotaan","Pedesaan") -> Pedesaan | C12: 415.11245
B13: =IF('Data Kumpulan'!B13=1,"Perkotaan","Pedesaan") -> Pedesaan | C13: 238.97449
B14: =IF('Data Kumpulan'!B14=1,"Perkotaan","Pedesaan") -> Pedesaan | C14: 108.93455
... B18: =IF('Data Kumpulan'!B18=1,"Perkotaan","Pedesaan") -> Pedesaan | C18: 659.15838
B19: =IF('Data Kumpulan'!B20=1,"Perkotaan","Pedesaan") -> Perkotaan | C19: 618.10717
B20: =IF('Data Kumpulan'!B21=1,"Perkotaan","Pedesaan") -> Pedesaan | C20: 115.90344
B21: =IF('Data Kumpulan'!B22=1,"Perkotaan","Pedesaan") -> Perkotaan | C21: 926.37082
B22: =IF('Data Kumpulan'!B23=1,"Perkotaan","Pedesaan") -> Perkotaan | C22: 320.36129
B23: =IF('Data Kumpulan'!B25=1,"Perkotaan","Pedesaan") -> Pedesaan | C23: 694.26308
B24: =IF('Data Kumpulan'!B26=1,"Perkotaan","Pedesaan") -> Pedesaan | C24: 1666.1075
B25: =IF('Data Kumpulan'!B27=1,"Perkotaan","Pedesaan") -> Pedesaan | C25: 278.15187
B26: =IF('Data Kumpulan'!B28=1,"Perkotaan","Pedesaan") -> Perkotaan | C26: 1202.7173
B27: =IF('Data Kumpulan'!B29=1,"Perkotaan","Pedesaan") -> Perkotaan | C27: 434.30323
B28: =IF('Data Kumpulan'!B30=1,"Perkotaan","Pedesaan") -> Perkotaan | C28: 580.66592
B29: =IF('Data Kumpulan'!B31=1,"Perkotaan","Pedesaan") -> Pedesaan | C29: 26.26904
B30: =IF('Data Kumpulan'!B32=1,"Perkotaan","Pedesaan") -> Pedesaan | C30: 81.600867
B31: =IF('Data Kumpulan'!B33=1,"Perkotaan","Pedesaan") -> Perkotaan | C31: 583.02486
B32: =IF('Data Kumpulan'!B34=1,"Perkotaan","Pedesaan") -> Perkotaan | C32: 1223.1926
B33: =IF('Data Kumpulan'!B35=1,"Perkotaan","Pedesaan") -> Pedesaan | C33: 191.76652
B34: =IF('Data Kumpulan'!B36=1,"Perkotaan","Pedesaan") -> Perkotaan | C34: 645.09883
... B56: =IF('Data Kumpulan'!B58=1,"Perkotaan","Pedesaan") -> Pedesaan | C56: 330.26255
B57: =IF('Data Kumpulan'!B60=1,"Perkotaan","Pedesaan") -> Pedesaan | C57: 29.697536
B58: =IF('Data Kumpulan'!B61=1,"Perkotaan","Pedesaan") -> Pedesaan | C58: 112.86493
B59: =IF('Data Kumpulan'!B62=1,"Perkotaan","Pedesaan") -> Perkotaan | C59: 463.01798
B60: =IF('Data Kumpulan'!B63=1,"Perkotaan","Pedesaan") -> Perkotaan | C60: 1374.4486
B61: =IF('Data Kumpulan'!B64=1,"Perkotaan","Pedesaan") -> Perkotaan | C61: 1381.3344
B62: =IF('Data Kumpulan'!B65=1,"Perkotaan","Pedesaan") -> Pedesaan | C62: 219.67191
B63: =IF('Data Kumpulan'!B66=1,"Perkotaan","Pedesaan") -> Pedesaan | C63: 1442.8419
B64: =IF('Data Kumpulan'!B67=1,"Perkotaan","Pedesaan") -> Pedesaan | C64: 894.95748
...

Sheet Kondisi Fisik
A1: KESELURUHAN | H1: PERKOTAAN | O1: PEDESAAN
A2: keruh | B2: berwarna | C2: berasa | D2: berbusa | E2: berbau | H2: keruh | I2: berwarna | J2: berasa | K2: berbusa | L2: berbau | O2: keruh | P2: berwarna | Q2: berasa | R2: berbusa | S2: berbau
A3: 627.84242 | B3: 323.34749 | C3: 323.34749 | D3: 192.62681 | E3: 192.62681 | H3: 627.84242 | I3: 572.53686 | J3: 572.53686 | O3: 607.311 | P3: 323.34749 | Q3: 323.34749 | R3: 192.62681 | S3: 192.62681
A4: 607.311 | B4: 171.53427 | C4: 171.53427 | D4: 793.54916 | E4: 793.54916 | H4: 479.50848 | I4: 1243.9021 | J4: 1243.9021 | O4: 222.2414 | P4: 171.53427 | Q4: 171.53427 | R4: 793.54916 | S4: 793.54916
A5: 479.50848 | B5: 113.10445 | C5: 113.10445 | E5: 105.16774 | H5: 76.295354 | I5: 1342.0709 | J5: 1342.0709 | O5: 192.62681 | P5: 113.10445 | Q5: 113.10445 | S5: 105.16774
A6: 76.295354 | B6: 222.2414 | C6: 572.53686 | H6: 1243.9021 | I6: 607.0187 | J6: 607.0187 | O6: 418.96966 | P6: 222.2414 | Q6: 695.23206
A7: 222.2414 | B7: 572.53686 | C7: 1243.9021 | H7: 897.41062 | I7: 1251.9075 | J7: 1251.9075 | O7: 375.63948 | P7: 695.23206 | Q7: 276.40448
A8: 1243.9021 | B8: 1243.9021 | C8: 695.23206 | I8: 806.61083 | J8: 806.61083 | O8: 105.16774 | P8: 456.82133 | Q8: 192.62681
A9: 192.62681 | B9: 695.23206 | C9: 276.40448 | I9: 897.41062 | J9: 897.41062 | O9: 357.01737 | P9: 192.62681 | Q9: 793.54916
A10: 418.96966 | B10: 456.82133 | C10: 1342.0709 | I10: 532.61662 | J10: 532.61662 | O10: 1617.5829 | P10: 793.54916 | Q10: 758.25472
A11: 375.63948 | B11: 1342.0709 | C11: 192.62681 | I11: 410.13319 | J11: 624.51938 | O11: 367.58647 | P11: 758.25472 | Q11: 443.41598
A12: 105.16774 | B12: 192.62681 | C12: 793.54916 | I12: 624.51938 | O12: 531.94037 | P12: 443.41598 | Q12: 1039.9771
A13: 357.01737 | B13: 793.54916 | C13: 758.25472 | P13: 1039.9771 | Q13: 105.16774
A14: 1617.5829 | B14: 758.25472 | C14: 607.0187 | P14: 357.01737 | Q14: 357.01737
A15: 897.41062 | B15: 607.0187 | C15: 1251.9075 | P15: 1209.6795 | Q15: 1209.6795
A16: 367.58647 | B16: 1251.9075 | C16: 443.41598
A17: 531.94037 | B17: 443.41598 | C17: 1039.9771
B18: 1039.9771 | C18: 105.16774
B19: 357.01737 | C19: 357.01737
B20: 806.61083 | C20: 806.61083
B21: 897.41062 | C21: 897.41062
B22: 532.61662 | C22: 532.61662
B23: 410.13319 | C23: 624.51938
B24: 624.51938 | C24: 1209.6795
B25: 1209.6795
A26: =SUM(A3:A25) -> 8121.0422 | B26: =SUM(B3:B25) -> 15065.528 | C26: =SUM(C3:C25) -> 14357.905 | D26: =SUM(D3:D25) -> 986.17596 | E26: =SUM(E3:E25) -> 1091.3437 | H26: =SUM(H3:H25) -> 3324.959 | I26: =SUM(I3:I25) -> 8288.7267 | J26: =SUM(J3:J25) -> 7878.5935 | K26: =SUM(K3:K25) -> 0 | L26: =SUM(L3:L25) -> 0 | O26: =SUM(O3:O25) -> 4796.0832 | P26: =SUM(P3:P25) -> 6776.8016 | Q26: =SUM(Q3:Q25) -> 6479.3111 | R26: =SUM(R3:R25) -> 986.17596 | S26: =SUM(S3:S25) -> 1091.3437
A27: =1-(A26/$C$28) -> 0.9878613 | B27: =1-(B26/$C$28) -> 0.97748122 | C27: =1-(C26/$C$28) -> 0.97853892 | D27: =1-(D26/$C$28) -> 0.99852594 | E27: =1-(E26/$C$28) -> 0.99836874 | F27: 0.96928379 | H27: =1-(H26/$J$28) -> 0.99152891 | I27: =1-(I26/$J$28) -> 0.97888259 | J27: =1-(J26/$J$28) -> 0.97992749 | K27: =1-(K26/$J$28) -> 1 | L27: =1-(L26/$J$28) -> 1 | M27: 0.97586698 | O27: =1-(O26/$Q$28) -> 0.98265518 | P27: =1-(P26/$Q$28) -> 0.975492 | Q27: =1-(Q26/$Q$28) -> 0.97656786 | R27: =1-(R26/$Q$28) -> 0.99643354 | S27: =1-(S26/$Q$28) -> 0.9960532 | T27: 0.95993907
A28: bobot total | C28: =SUM('Data Kumpulan'!C:C) -> 669020.59 | H28: bobot total | J28: 392506.71 | O28: bobot total | Q28: 276513.89
A29: 0.9878613 | B29: 0.97748122 | C29: 0.97853892 | D29: 0.99852594 | E29: 0.99836874 | F29: =1-F27 -> 0.03071621
A30: 0.012138703 | B30: 0.022518781 | C30: 0.02146108 | D30: 0.0014740592 | E30: 0.0016312558
A32: Part to whole | O32: keruh | P32: tidak
B33: keruh | C33: warna | D33: rasa | E33: busa | F33: bau | O33: =A26 -> 8121.0422 | P33: =C28-A26 -> 660899.55
A34: kota | B34: =H26/A26 -> 0.40942516 | C34: =I26/B26 -> 0.5501783 | D34: =J26/C26 -> 0.54872864 | E34: =K26/D26 -> 0 | F34: =L26/E26 -> 0 | N34: kota | O34: =B34 -> 0.40942516
A35: desa | B35: =O26/A26 -> 0.59057484 | C35: =P26/B26 -> 0.4498217 | D35: =Q26/C26 -> 0.45127136 | E35: =R26/D26 -> 1 | F35: =S26/E26 -> 1 | N35: desa | O35: =B35 -> 0.59057484
F38: keseluruhan
F39: di tiap desa kota baru cari prop | N39: keruh | O39: perkotaan | P39: =H26 -> 3324.959
F40: prop karakteristik baru dikategori desa kota | O40: pedesaan | P40: =O26 -> 4796.0832
C41: =D27 -> 0.99852594 | N41: tidak | O41: perkotaan | P41: =J28-H26 -> 389181.75
C42: =1-C41 -> 0.0014740592 | O42: pedesaan | P42: =Q28-O26 -> 271717.8

Sheet Sumber Air Minum
A1: 1 | B1: 2 | C1: 3 | D1: 4 | E1: 5 | F1: 6 | G1: 7 | H1: 8 | I1: 9 | K1: proporsi total
A2: 736.95718 | B2: 406.9041 | C2: 933.07639 | D2: 28.466245 | E2: 479.50848 | F2: 323.34749 | G2: 1243.9021 | H2: 572.53686 | I2: 607.311 | K2: 0.02552458 | L2: 0.16171041 | M2: 0.04817736 | N2: 0.11849199 | O2: 0.2688137 | P2: 0.05889904 | Q2: 0.21165741 | R2: 0.084436803 | S2: 0.022255975
A3: 398.99441 | B3: 627.84242 | C3: 980.13121 | D3: 108.93455 | E3: 120.27253 | F3: 171.53427 | G3: 793.54916 | H3: 456.82133 | I3: 222.2414 | K3: =K2*100 -> 2.552458 | L3: =L2*100 -> 16.171041 | M3: =M2*100 -> 4.817736 | N3: =N2*100 -> 11.849199 | O3: =O2*100 -> 26.88137 | P3: =P2*100 -> 5.889904 | Q3: =Q2*100 -> 21.165741 | R3: =R2*100 -> 8.4436803 | S3: =S2*100 -> 2.2255975
A4: 550.33784 | B4: 115.90344 | C4: 2130.604 | D4: 1043.3126 | E4: 1044.4816 | F4: 415.11245 | G4: 1449.6065 | H4: 276.40448 | I4: 375.63948 | K4: perkotaan
A5: 673.1056 | B5: 926.37082 | C5: 828.93097 | D5: 618.10717 | E5: 420.70705 | F5: 694.26308 | G5: 26.987807 | H5: 192.62681 | I5: 357.01737 | K5: 0.041273181 | L5: 0.26020554 | M5: 0.077505182 | N5: 0.18268929 | O5: 0.27262023 | P5: 0.0086724436 | Q5: 0.13018376 | R5: 0.021204826 | S5: 0.0056455451
A6: 983.86842 | B6: 320.36129 | C6: 681.50197 | D6: 656.95093 | E6: 434.30323 | F6: 278.15187 | G6: 138.35535 | H6: 806.61083 | I6: 1617.5829 | K6: =K5*100 -> 4.1273181 | L6: =L5*100 -> 26.020554 | M6: =M5*100 -> 7.7505182 | N6: =N5*100 -> 18.268929 | O6: =O5*100 -> 27.262023 | P6: =P5*100 -> 0.86724436 | Q6: =Q5*100 -> 13.018376 | R6: =R5*100 -> 2.1204826 | S6: =S5*100 -> 0.56455451
A7: 907.7022 | B7: 1202.7173 | C7: 362.37418 | D7: 152.31384 | E7: 583.02486 | F7: 131.51102 | G7: 722.57353 | H7: 411.07108 | I7: 894.95748 | K7: pedesaan
A8: 620.89357 | B8: 645.09883 | C8: 840.10724 | D8: 1323.4522 | E8: 1223.1926 | F8: 1246.1946 | G8: 2133.0715 | H8: 897.41062 | I8: 399.49506 | K8: 0.0031660882 | L8: 0.021891015 | M8: 0.0065361712 | N8: 0.02735057 | O8: 0.26339231 | P8: 0.13017313 | Q8: 0.32728254 | R8: 0.17440652 | S8: 0.045801647
A9: 926.08703 | B9: 557.96053 | C9: 719.45588 | D9: 457.77991 | E9: 318.5353 | F9: 600.49719 | G9: 659.15838 | H9: 238.97449 | I9: 639.13847 | K9: =K8*100 -> 0.31660882 | L9: =L8*100 -> 2.1891015 | M9: =M8*100 -> 0.65361712 | N9: =N8*100 -> 2.735057 | O9: =O8*100 -> 26.339231 | P9: =P8*100 -> 13.017313 | Q9: =Q8*100 -> 32.728254 | R9: =R8*100 -> 17.440652 | S9: =S8*100 -> 4.5801647
A10: 658.17829 | B10: 393.00533 | C10: 587.8834 | D10: 112.86493 | E10: 343.14677 | F10: 392.46559 | G10: 580.66592 | H10: 1062.638 | I10: 97.309656
A11: 1034.5512 | B11: 1556.7549 | C11: 635.07664 | D11: 784.0205 | E11: 614.6349 | F11: 514.48579 | G11: 26.26904 | H11: 1666.1075 | I11: 1033.1195
A12: 727.1003 | B12: 1374.4486 | C12: 532.96544 | D12: 519.27722 | E12: 1370.1973 | F12: 981.68232 | G12: 81.600867 | H12: 366.14093 | I12: 690.02288
A13: 723.85608 | B13: 781.10087 | C13: 1620.2055 | D13: 505.46008 | E13: 823.62448 | F13: 1739.1095 | G13: 191.76652 | H13: 547.05535 | I13: 128.45402
A14: 875.46736 | B14: 687.87431 | C14: 511.29786 | D14: 303.48175 | E14: 373.22146 | F14: 966.17659 | G14: 929.88506 | H14: 634.71874 | I14: 482.78674 | L14: Perkotaan | M14: Air kemasan | O14: 0.041
A15: 459.73821 | B15: 661.36819 | C15: 352.32942 | D15: 495.26952 | E15: 472.28641 | F15: 424.369 | G15: 91.741886 | H15: 461.58522 | I15: 570.56248 | M15: Air isi ulang | O15: 0.26
A16: 696.04185 | B16: 597.45037 | C16: 987.75414 | D16: 474.39862 | E16: 936.2 | F16: 648.16117 | G16: 120.46721 | H16: 267.6835 | I16: 812.71662 | M16: Leding | O16: 0.078
A17: 671.40005 | B17: 453.46882 | C17: 573.20623 | D17: 397.35322 | E17: 247.34997 | F17: 486.59645 | G17: 330.26255 | H17: 691.14951 | I17: 2.9434125 | M17: Sumur bor/pompa | O17: 0.183
A18: 345.76109 | B18: 468.29392 | C18: 408.55338 | D18: 596.80682 | E18: 1003.5195 | F18: 217.62065 | G18: 463.01798 | H18: 352.99414 | I18: 128.45402 | M18: Sumur terlindung | O18: 0.273
A19: 353.18264 | B19: 774.92139 | C19: 562.60364 | D19: 668.40601 | E19: 29.697536 | F19: 811.9829 | G19: 1381.3344 | H19: 154.16119 | I19: 624.82721 | M19: Sumur tak terlindung | O19: 0.009
A20: 182.37658 | B20: 105.6831 | C20: 425.42656 | D20: 512.98302 | E20: 412.07063 | F20: 242.76972 | G20: 219.67191 | H20: 616.14728 | I20: 764.05918 | M20: Mata air terlindung | O20: 0.13
A21: 13.455431 | B21: 544.83323 | C21: 554.06367 | D21: 529.26856 | E21: 28.849035 | F21: 460.56778 | G21: 1442.8419 | H21: 701.94729 | I21: 325.30919 | M21: Mata air tak terlindung | O21: 0.021
A22: 555.4739 | B22: 1264.0979 | C22: 575.43888 | D22: 616.59229 | E22: 461.94618 | F22: 728.18196 | G22: 880.29119 | H22: 130.96406 | I22: 870.93705 | M22: Air permukaan | O22: 0.006
A23: 478.26041 | B23: 116.89766 | C23: 497.00201 | D23: 991.36534 | E23: 1034.6253 | F23: 903.25981 | G23: 358.33952 | H23: 19.669797 | I23: 296.98557 | L23: Pedesaan | M23: Air kemasan | O23: 0.003
A24: 1527.8155 | B24: 514.36947 | C24: 676.33586 | D24: 1697.6344 | E24: 455.43578 | F24: 408.26594 | G24: 328.38065 | H24: 687.33514 | I24: 961.03055 | M24: Air isi ulang | O24: 0.022
A25: 726.91061 | B25: 791.96165 | C25: 284.18781 | D25: 880.64575 | E25: 1307.0923 | F25: 426.57191 | G25: 1193.9316 | H25: 36.947351 | I25: 390.33164 | M25: Leding | O25: 0.007
A26: 1247.9542 | B26: 1069.4126 | C26: 1103.8355 | D26: 989.43421 | E26: 1609.5857 | F26: 813.76077 | G26: 92.377684 | H26: 132.9551 | I26: 659.79855 | M26: Sumur bor/pompa | O26: 0.027
B27: 1254.8731 | C27: 527.21413 | D27: 591.69554 | E27: 128.33462 | F27: 213.86801 | G27: 86.480917 | H27: 504.3158 | I27: 203.52974 | M27: Sumur terlindung | O27: 0.263
B28: 644.15963 | C28: 772.60254 | D28: 30.977242 | E28: 427.39549 | F28: 586.2724 | G28: 263.33809 | H28: 1066.3101 | I28: 27.346481 | M28: Sumur tak terlindung | O28: 0.13
B29: 161.8004 | C29: 920.98337 | D29: 686.78426 | E29: 381.19632 | F29: 452.93932 | G29: 588.12797 | H29: 134.81958 | I29: 125.86295 | M29: Mata air terlindung | O29: 0.327
B30: 27.087262 | C30: 697.69246 | D30: 918.30768 | E30: 542.89754 | F30: 421.15725 | G30: 1104.0132 | H30: 841.9394 | I30: 221.24433 | M30: Mata air tak terlindung | O30: 0.174
B31: 191.09542 | C31: 1192.1627 | D31: 455.21694 | E31: 1050.6789 | F31: 71.508428 | G31: 566.01704 | H31: 769.56406 | I31: 349.69084 | M31: Air permukaan | O31: 0.046
B32: 1124.5833 | C32: 1054.5633 | D32: 642.52504 | E32: 381.4091 | F32: 889.49205 | G32: 427.20635 | H32: 316.68531
B33: 136.57209 | C33: 854.71756 | D33: 715.11765 | E33: 1400.47 | F33: 879.21076 | G33: 169.46051 | H33: 410.88348
B34: 666.36416 | C34: 569.5574 | D34: 177.54966 | E34: 26.26904 | F34: 707.12299 | G34: 519.15895 | H34: 410.90162
B35: 1263.0458 | C35: 374.75966 | D35: 933.03767 | E35: 948.33091 | F35: 649.89297 | G35: 1022.3867 | H35: 308.9733
B36: 1671.1677 | C36: 442.43045 | D36: 500.52594 | E36: 1019.3122 | F36: 259.62079 | G36: 585.04413 | H36: 36.947351
B37: 1365.0635 | C37: 815.78697 | D37: 1101.8914 | E37: 131.79928 | F37: 511.59164 | G37: 97.304406 | H37: 526.6573
B38: 582.09504 | C38: 778.44482 | D38: 1008.6014 | E38: 317.31664 | F38: 217.60554 | G38: 740.4037 | H38: 621.8285
B39: 113.10445 | C39: 929.16042 | D39: 471.98321 | E39: 697.71843 | F39: 359.11299 | G39: 322.62083 | H39: 531.57435
B40: 119.01528 | C40: 1063.9753 | D40: 139.49758 | E40: 380.14714 | F40: 654.41795 | G40: 330.18627 | H40: 368.83162
...

Sheet Sheet6
B1: 2019 | C1: 2020 | D1: 2021 | E1: 2022 | F1: 2023
A3: Bogor | B3: 91.02 | C3: 92.13 | D3: 91.83 | E3: 92.28 | F3: 91.9 | I3: Garut | J3: Jawa Barat | K3: Nasional
A4: Sukabumi | B4: 79.57 | C4: 79.98 | D4: 81.34 | E4: 85.7 | F4: 85.72 | I4: =B7 -> 84.17 | J4: =B30 -> 92.3 | K4: 89.7
A5: Cianjur | B5: 81.5 | C5: 82.73 | D5: 86.25 | E5: 80.79 | F5: 85.65 | I5: =C7 -> 81.86 | J5: =C30 -> 93.42 | K5: 90.21
A6: Bandung | B6: 97.84 | C6: 95.87 | D6: 99.07 | E6: 93.79 | F6: 95.73 | I6: =D7 -> 77.35 | J6: =D30 -> 93.24 | K6: 90.78
A7: Garut | B7: 84.17 | C7: 81.86 | D7: 77.35 | E7: 78.15 | F7: 81.13 | I7: =E7 -> 78.15 | J7: =E30 -> 93.04 | K7: 91.05
A8: Tasikmalaya | B8: 76.18 | C8: 85.17 | D8: 85.26 | E8: 89.35 | F8: 89.03 | I8: =F7 -> 81.13 | J8: =F30 -> 93.86 | K8: 91.72
A9: Ciamis | B9: 82.8 | C9: 89.4 | D9: 90.12 | E9: 93.8 | F9: 94.39
A10: Kuningan | B10: 94.26 | C10: 93.37 | D10: 94.4 | E10: 95.51 | F10: 96.57
A11: Cirebon | B11: 95.55 | C11: 96.12 | D11: 96.54 | E11: 94.99 | F11: 98.52
A12: Majalengka | B12: 97.95 | C12: 97.19 | D12: 96.8 | E12: 95.7 | F12: 93.38
A13: Sumedang | B13: 89.77 | C13: 94.96 | D13: 94.16 | E13: 95.84 | F13: 95.42
A14: Indramayu | B14: 95.25 | C14: 98.14 | D14: 97.95 | E14: 95.25 | F14: 97.77
A15: Subang | B15: 98.33 | C15: 97.78 | D15: 98.75 | E15: 98.01 | F15: 99.22
A16: Purwakarta | B16: 82.34 | C16: 80.37 | D16: 81.5 | E16: 92.59 | F16: 85.4
A17: Karawang | B17: 95.84 | C17: 97.62 | D17: 96.63 | E17: 98.19 | F17: 98.11
A18: Bekasi | B18: 96.07 | C18: 98.23 | D18: 95.02 | E18: 94.86 | F18: 96.95
A19: Bandung Barat | B19: 92.17 | C19: 93.26 | D19: 92.47 | E19: 86.6 | F19: 92.27
A20: Pangandaran | B20: 83.65 | C20: 90.91 | D20: 80.78 | E20: 84.14 | F20: 82.95
... A31: Indonesia | B31: 89.7 | C31: 90.21 | D31: 90.78 | E31: 91.05 | F31: 91.72
